Workbook

Sheet Компании
A1: № | B1: Компании | C1: Страна | D1: Развитая/Развивающая | E1: Комментарий | F1: Ссылка на данные
A2: 1 | B2: BYD | C2: Китай | D2: Развивающая | F2: https://finance.yahoo.com/quote/1211.HK/
A3: 2 | B3: Tesla | C3: США | D3: Развитая | F3: https://finance.yahoo.com/quote/TSLA/
A4: 3 | B4: Volvo | C4: Швеция | D4: Развитая | E4: IPO в 2021 | F4: https://finance.yahoo.com/quote/VOLCAR-B.ST/
A5: 4 | B5: KIA | C5: Южная Корея | D5: Развитая | F5: https://finance.yahoo.com/quote/000270.KS/
A6: 5 | B6: Toyota | C6: Япония | D6: Развитая | F6: https://finance.yahoo.com/quote/7203.T/
A7: 6 | B7: Audi | C7: Германия | D7: Развитая | E7: Не торгуется, дочерняя компания Volkswagen, убираем из выборки | F7: ***
A8: 7 | B8: Hyundai | C8: Южная Корея | D8: Развитая | F8: https://finance.yahoo.com/quote/005380.KS/
A9: 8 | B9: Volkswagen | C9: Германия | D9: Развитая | F9: https://finance.yahoo.com/quote/VOW3.DE/
A10: 9 | B10: BMW | C10: Германия | D10: Развитая | F10: https://finance.yahoo.com/quote/BMW.DE/
A11: 10 | B11: AITO (Seres) | C11: Китай | D11: Развивающая | E11: IPO в 2025, из выборки убираем | F11: https://finance.yahoo.com/quote/9927.HK/
A12: 11 | B12: Aion (GAC) | C12: Китай | D12: Развивающая | F12: https://finance.yahoo.com/quote/2238.HK/
A13: 12 | B13: Mercedes-Benz | C13: Германия | D13: Развитая | F13: https://finance.yahoo.com/quote/MBG.DE/
A14: 13 | B14: Li Auto | C14: Китай | D14: Развивающая | E14: IPO в 2021 в Hong Kong, на NASDAQ в 2020 | F14: https://finance.yahoo.com/quote/2015.HK/
A15: 14 | B15: Geely | C15: Китай | D15: Развивающая | F15: https://finance.yahoo.com/quote/0175.HK/
A16: 15 | B16: Chery | C16: Китай | D16: Развивающая | E16: IPO в 2025, из выборки убираем | F16: https://finance.yahoo.com/quote/9973.HK/
A17: 16 | B17: Wuling (SGMW) | C17: Китай | D17: Развивающая | F17: https://finance.yahoo.com/quote/600104.SS/
A18: 17 | B18: BAIC Motor Corporation Limited | C18: Китай | D18: Развивающая | F18: https://finance.yahoo.com/quote/1958.HK/
A19: 18 | B19: XPeng | C19: Китай | D19: Развивающая | E19: IPO в 2021 в Hong Kong, на NASDAQ в 2020 | F19: https://finance.yahoo.com/quote/9868.HK/
A20: 19 | B20: Nissan | C20: Япония | D20: Развитая | F20: https://finance.yahoo.com/quote/7201.T/

Sheet analysis
D2: Развитые | E2: Развивающиеся | F2: Все
C3: 2021 | D3: =AVERAGE(Tesla!L8,KIA!L8,Toyota!L8,Hyndai!L8,Volkswagen!L8,BMW!L8,'Mercedes-Benz'!L8,Nissan!L8) -> 79.777926 | E3: =AVERAGE(BYD!L8,'Aion(GAC)'!L8,Geely!L8,'Wuling(SGMW)'!L8,BAIC!L8) -> 39.280316 | F3: =AVERAGE(Tesla!L8,KIA!L8,Toyota!L8,Hyndai!L8,Volkswagen!L8,BMW!L8,'Mercedes-Benz'!L8,Nissan!L8,BYD!L8,'Aion(GAC)'!L8,Geely!L8,'Wuling(SGMW)'!L8,BAIC!L8) -> 64.201922
C4: 2022 | D4: =AVERAGE(Tesla!L9,KIA!L9,Toyota!L9,Hyndai!L9,Volkswagen!L9,BMW!L9,'Mercedes-Benz'!L9,Volvo!L9,Nissan!L9) -> -4.3162962 | E4: =AVERAGE(BYD!L9,'Aion(GAC)'!L9,Geely!L9,'Wuling(SGMW)'!L9,LiAuto!L9,BAIC!L9,XPeng!L9) -> -23.919357 | F4: =AVERAGE(Tesla!L9,KIA!L9,Toyota!L9,Hyndai!L9,Volkswagen!L9,BMW!L9,'Mercedes-Benz'!L9,Volvo!L9,Nissan!L9,BYD!L9,'Aion(GAC)'!L9,Geely!L9,'Wuling(SGMW)'!L9,LiAuto!L9,BAIC!L9,XPeng!L9) -> -12.892635
C5: 2023 | D5: =AVERAGE(Tesla!L10,KIA!L10,Toyota!L10,Hyndai!L10,Volkswagen!L10,BMW!L10,'Mercedes-Benz'!L10,Volvo!L10,Nissan!L10) -> 5.4006172 | E5: =AVERAGE(BYD!L10,'Aion(GAC)'!L10,Geely!L10,'Wuling(SGMW)'!L10,LiAuto!L10,BAIC!L10,XPeng!L10) -> -7.0628795 | F5: =AVERAGE(Tesla!L10,KIA!L10,Toyota!L10,Hyndai!L10,Volkswagen!L10,BMW!L10,'Mercedes-Benz'!L10,Volvo!L10,Nissan!L10,BYD!L10,'Aion(GAC)'!L10,Geely!L10,'Wuling(SGMW)'!L10,LiAuto!L10,BAIC!L10,XPeng!L10) -> -0.052162563
C6: 2024 | D6: =AVERAGE(Tesla!L11,KIA!L11,Toyota!L11,Hyndai!L11,Volkswagen!L11,BMW!L11,'Mercedes-Benz'!L11,Volvo!L11,Nissan!L11) -> 7.2411605 | E6: =AVERAGE(BYD!L11,'Aion(GAC)'!L11,Geely!L11,'Wuling(SGMW)'!L11,LiAuto!L11,BAIC!L11,XPeng!L11) -> -5.0592604 | F6: =AVERAGE(Tesla!L11,KIA!L11,Toyota!L11,Hyndai!L11,Volkswagen!L11,BMW!L11,'Mercedes-Benz'!L11,Volvo!L11,Nissan!L11,BYD!L11,'Aion(GAC)'!L11,Geely!L11,'Wuling(SGMW)'!L11,LiAuto!L11,BAIC!L11,XPeng!L11) -> 1.8597263
C7: 2025 | D7: =AVERAGE(Tesla!L12,KIA!L12,Toyota!L12,Hyndai!L12,Volkswagen!L12,BMW!L12,'Mercedes-Benz'!L12,Volvo!L12,Nissan!L12) -> -2.8680694 | E7: =AVERAGE(BYD!L12,'Aion(GAC)'!L12,Geely!L12,'Wuling(SGMW)'!L12,LiAuto!L12,BAIC!L12,XPeng!L12) -> 32.695231 | F7: =AVERAGE(Tesla!L12,KIA!L12,Toyota!L12,Hyndai!L12,Volkswagen!L12,BMW!L12,'Mercedes-Benz'!L12,Volvo!L12,Nissan!L12,BYD!L12,'Aion(GAC)'!L12,Geely!L12,'Wuling(SGMW)'!L12,LiAuto!L12,BAIC!L12,XPeng!L12) -> 12.690875
J86: Названия строк | K86: Sum of Прирост 2025 г
J87: Развивающая | K87: 2.2886662
J88: XPeng | K88: 1.0274066
J89: Geely | K89: 0.61075188
J90: BYD | K90: 0.55164296
J91: Aion (GAC) | K91: 0.092460947
J92: Wuling (SGMW) | K92: 0.05435231
J93: BAIC | K93: -0.022790317
J94: Li Auto | K94: -0.025158166
J95: Развитая | K95: -0.25812624
J96: Tesla | K96: 0.43763634
J97: Hyundai | K97: 0.00086668969
J98: KIA | K98: -0.0064325381
... J105: Общий итог | K105: 2.0305399

Sheet BYD
A1: Close | B1: Volume | C1: date | D1: Year | E1: Close * Volume
A2: 12.686366 | B2: 12976863 | C2: 2020-01-02 00:00:00+08:00 | D2: =LEFT(C2,4) -> 2020 | E2: =A2*B2 -> 1.6462923e+08
A3: 12.654127 | B3: 14749896 | C3: 2020-01-03 00:00:00+08:00 | D3: =LEFT(C3,4) -> 2020 | E3: =A3*B3 -> 1.8664706e+08
A4: 12.476809 | B4: 8659776 | C4: 2020-01-06 00:00:00+08:00 | D4: =LEFT(C4,4) -> 2020 | E4: =A4*B4 -> 1.0804637e+08
A5: 12.476809 | B5: 7455444 | C5: 2020-01-07 00:00:00+08:00 | D5: =LEFT(C5,4) -> 2020 | E5: =A5*B5 -> 93020147 | K5: Ср.Взвеш | L5: Прирост
A6: 12.331731 | B6: 12046377 | C6: 2020-01-08 00:00:00+08:00 | D6: =LEFT(C6,4) -> 2020 | E6: =A6*B6 -> 1.4855268e+08
A7: 12.509048 | B7: 7564284 | C7: 2020-01-09 00:00:00+08:00 | D7: =LEFT(C7,4) -> 2020 | E7: =A7*B7 -> 94621995 | H7: 2020 | I7: =SUMIF(D:D,$H7,E:E) -> 2.4479692e+11 | J7: =SUMIF($D:$D,$H7,B:B) -> 7917473547 | K7: =I7/J7 -> 30.918565
A8: 12.492929 | B8: 6810102 | C8: 2020-01-10 00:00:00+08:00 | D8: =LEFT(C8,4) -> 2020 | E8: =A8*B8 -> 85078117 | H8: 2021 | I8: =SUMIF(D:D,$H8,E:E) -> 6.0330104e+11 | J8: =SUMIF($D:$D,$H8,B:B) -> 8051410650 | K8: =I8/J8 -> 74.931098 | L8: =(K8-K7)*100/K7 -> 142.34986
A9: 14.475677 | B9: 87083133 | C9: 2020-01-13 00:00:00+08:00 | D9: =LEFT(C9,4) -> 2020 | E9: =A9*B9 -> 1.2605873e+09 | H9: 2022 | I9: =SUMIF(D:D,$H9,E:E) -> 4.599333e+11 | J9: =SUMIF($D:$D,$H9,B:B) -> 6082211943 | K9: =I9/J9 -> 75.619413 | L9: =(K9-K8)*100/K8 -> 0.9185968
A10: 14.524036 | B10: 75874131 | C10: 2020-01-14 00:00:00+08:00 | D10: =LEFT(C10,4) -> 2020 | E10: =A10*B10 -> 1.1019986e+09 | H10: 2023 | I10: =SUMIF(D:D,$H10,E:E) -> 3.9948857e+11 | J10: =SUMIF($D:$D,$H10,B:B) -> 5251749741 | K10: =I10/J10 -> 76.067709 | L10: =(K10-K9)*100/K9 -> 0.59283181
A11: 14.749716 | B11: 31078974 | C11: 2020-01-15 00:00:00+08:00 | D11: =LEFT(C11,4) -> 2020 | E11: =A11*B11 -> 4.5840603e+08 | H11: 2024 | I11: =SUMIF(D:D,$H11,E:E) -> 4.0060248e+11 | J11: =SUMIF($D:$D,$H11,B:B) -> 5318479425 | K11: =I11/J11 -> 75.322747 | L11: =(K11-K10)*100/K10 -> -0.979341
A12: 14.669115 | B12: 14694996 | C12: 2020-01-16 00:00:00+08:00 | D12: =LEFT(C12,4) -> 2020 | E12: =A12*B12 -> 2.1556259e+08 | H12: 2025 | I12: =SUMIF(D:D,$H12,E:E) -> 9.7415625e+11 | J12: =SUMIF($D:$D,$H12,B:B) -> 8335097351 | K12: =I12/J12 -> 116.87401 | L12: =(K12-K11)*100/K11 -> 55.164296
A13: 15.475112 | B13: 62838537 | C13: 2020-01-17 00:00:00+08:00 | D13: =LEFT(C13,4) -> 2020 | E13: =A13*B13 -> 9.724334e+08
A14: 15.53959 | B14: 41107242 | C14: 2020-01-20 00:00:00+08:00 | D14: =LEFT(C14,4) -> 2020 | E14: =A14*B14 -> 6.3878968e+08
A15: 14.701356 | B15: 27175455 | C15: 2020-01-21 00:00:00+08:00 | D15: =LEFT(C15,4) -> 2020 | E15: =A15*B15 -> 3.9951604e+08
A16: 15.297793 | B16: 29762829 | C16: 2020-01-22 00:00:00+08:00 | D16: =LEFT(C16,4) -> 2020 | E16: =A16*B16 -> 4.5530561e+08
A17: 14.943154 | B17: 24577659 | C17: 2020-01-23 00:00:00+08:00 | D17: =LEFT(C17,4) -> 2020 | E17: =A17*B17 -> 3.6726775e+08
A18: 14.894794 | B18: 10589667 | C18: 2020-01-24 00:00:00+08:00 | D18: =LEFT(C18,4) -> 2020 | E18: =A18*B18 -> 1.577309e+08
A19: 13.927601 | B19: 24305643 | C19: 2020-01-29 00:00:00+08:00 | D19: =LEFT(C19,4) -> 2020 | E19: =A19*B19 -> 3.3851929e+08
A20: 13.427883 | B20: 25379982 | C20: 2020-01-30 00:00:00+08:00 | D20: =LEFT(C20,4) -> 2020 | E20: =A20*B20 -> 3.4079943e+08
A21: 13.250565 | B21: 15649476 | C21: 2020-01-31 00:00:00+08:00 | D21: =LEFT(C21,4) -> 2020 | E21: =A21*B21 -> 2.0736439e+08
A22: 13.363401 | B22: 32290134 | C22: 2020-02-03 00:00:00+08:00 | D22: =LEFT(C22,4) -> 2020 | E22: =A22*B22 -> 4.3150602e+08
A23: 14.153279 | B23: 32035044 | C23: 2020-02-04 00:00:00+08:00 | D23: =LEFT(C23,4) -> 2020 | E23: =A23*B23 -> 4.5340093e+08
A24: 15.136593 | B24: 67742310 | C24: 2020-02-05 00:00:00+08:00 | D24: =LEFT(C24,4) -> 2020 | E24: =A24*B24 -> 1.0253878e+09
... A1477: 95.099998 | B1477: 0 | C1477: 2025-12-31 00:00:00+08:00 | D1477: =LEFT(C1477,4) -> 2025 | E1477: =A1477*B1477 -> 0

Sheet Tesla
A1: Close | B1: Volume | C1: date | D1: Year | E1: Close * Volume
A2: 28.684 | B2: 142981500 | C2: 2020-01-02 00:00:00-05:00 | D2: =LEFT(C2,4) -> 2020 | E2: =A2*B2 -> 4.1012813e+09
A3: 29.534 | B3: 266677500 | C3: 2020-01-03 00:00:00-05:00 | D3: =LEFT(C3,4) -> 2020 | E3: =A3*B3 -> 7.8760534e+09
A4: 30.102667 | B4: 151995000 | C4: 2020-01-06 00:00:00-05:00 | D4: =LEFT(C4,4) -> 2020 | E4: =A4*B4 -> 4.5754548e+09
A5: 31.270666 | B5: 268231500 | C5: 2020-01-07 00:00:00-05:00 | D5: =LEFT(C5,4) -> 2020 | E5: =A5*B5 -> 8.3877777e+09 | K5: Ср.Взвеш | L5: Прирост
A6: 32.809334 | B6: 467164500 | C6: 2020-01-08 00:00:00-05:00 | D6: =LEFT(C6,4) -> 2020 | E6: =A6*B6 -> 1.5327356e+10
A7: 32.089333 | B7: 426606000 | C7: 2020-01-09 00:00:00-05:00 | D7: =LEFT(C7,4) -> 2020 | E7: =A7*B7 -> 1.3689502e+10 | H7: 2020 | I7: =SUMIF(D:D,$H7,E:E) -> 4.9090994e+12 | J7: =SUMIF($D:$D,$H7,B:B) -> 57158737200 | K7: =I7/J7 -> 85.885371
A8: 31.876667 | B8: 194392500 | C8: 2020-01-10 00:00:00-05:00 | D8: =LEFT(C8,4) -> 2020 | E8: =A8*B8 -> 6.196585e+09 | H8: 2021 | I8: =SUMIF(D:D,$H8,E:E) -> 5.3835721e+12 | J8: =SUMIF($D:$D,$H8,B:B) -> 20708071500 | K8: =I8/J8 -> 259.97457 | L8: =(K8-K7)*100/K7 -> 202.69948
A9: 34.990665 | B9: 397764000 | C9: 2020-01-13 00:00:00-05:00 | D9: =LEFT(C9,4) -> 2020 | E9: =A9*B9 -> 1.3918027e+10 | H9: 2022 | I9: =SUMIF(D:D,$H9,E:E) -> 5.5226208e+12 | J9: =SUMIF($D:$D,$H9,B:B) -> 21821019600 | K9: =I9/J9 -> 253.0872 | L9: =(K9-K8)*100/K8 -> -2.6492489
A10: 35.861332 | B10: 434943000 | C10: 2020-01-14 00:00:00-05:00 | D10: =LEFT(C10,4) -> 2020 | E10: =A10*B10 -> 1.5597635e+10 | H10: 2023 | I10: =SUMIF(D:D,$H10,E:E) -> 7.3149568e+12 | J10: =SUMIF($D:$D,$H10,B:B) -> 34337910000 | K10: =I10/J10 -> 213.0286 | L10: =(K10-K9)*100/K9 -> -15.827985
A11: 34.566666 | B11: 260532000 | C11: 2020-01-15 00:00:00-05:00 | D11: =LEFT(C11,4) -> 2020 | E11: =A11*B11 -> 9.0057225e+09 | H11: 2024 | I11: =SUMIF(D:D,$H11,E:E) -> 5.5573901e+12 | J11: =SUMIF($D:$D,$H11,B:B) -> 23899546500 | K11: =I11/J11 -> 232.53119 | L11: =(K11-K10)*100/K10 -> 9.1549196
A12: 34.232666 | B12: 326050500 | C12: 2020-01-16 00:00:00-05:00 | D12: =LEFT(C12,4) -> 2020 | E12: =A12*B12 -> 1.1161578e+10 | H12: 2025 | I12: =SUMIF(D:D,$H12,E:E) -> 7.3362077e+12 | J12: =SUMIF($D:$D,$H12,B:B) -> 21945291500 | K12: =I12/J12 -> 334.29529 | L12: =(K12-K11)*100/K11 -> 43.763634
A13: 34.033333 | B13: 204436500 | C13: 2020-01-17 00:00:00-05:00 | D13: =LEFT(C13,4) -> 2020 | E13: =A13*B13 -> 6.9576554e+09
A14: 36.48 | B14: 267052500 | C14: 2020-01-21 00:00:00-05:00 | D14: =LEFT(C14,4) -> 2020 | E14: =A14*B14 -> 9.7420751e+09
A15: 37.970669 | B15: 470535000 | C15: 2020-01-22 00:00:00-05:00 | D15: =LEFT(C15,4) -> 2020 | E15: =A15*B15 -> 1.7866529e+10
A16: 38.146667 | B16: 294765000 | C16: 2020-01-23 00:00:00-05:00 | D16: =LEFT(C16,4) -> 2020 | E16: =A16*B16 -> 1.1244302e+10
A17: 37.654667 | B17: 215304000 | C17: 2020-01-24 00:00:00-05:00 | D17: =LEFT(C17,4) -> 2020 | E17: =A17*B17 -> 8.1072004e+09
A18: 37.201332 | B18: 204121500 | C18: 2020-01-27 00:00:00-05:00 | D18: =LEFT(C18,4) -> 2020 | E18: =A18*B18 -> 7.5935917e+09
A19: 37.793331 | B19: 176827500 | C19: 2020-01-28 00:00:00-05:00 | D19: =LEFT(C19,4) -> 2020 | E19: =A19*B19 -> 6.6829003e+09
A20: 38.732666 | B20: 267022500 | C20: 2020-01-29 00:00:00-05:00 | D20: =LEFT(C20,4) -> 2020 | E20: =A20*B20 -> 1.0342493e+10
A21: 42.720669 | B21: 435085500 | C21: 2020-01-30 00:00:00-05:00 | D21: =LEFT(C21,4) -> 2020 | E21: =A21*B21 -> 1.8587144e+10
A22: 43.371334 | B22: 235789500 | C22: 2020-01-31 00:00:00-05:00 | D22: =LEFT(C22,4) -> 2020 | E22: =A22*B22 -> 1.0226505e+10
A23: 52 | B23: 705975000 | C23: 2020-02-03 00:00:00-05:00 | D23: =LEFT(C23,4) -> 2020 | E23: =A23*B23 -> 36710700000
A24: 59.137333 | B24: 914082000 | C24: 2020-02-04 00:00:00-05:00 | D24: =LEFT(C24,4) -> 2020 | E24: =A24*B24 -> 5.4056372e+10
... A1477: 401.98999 | B1477: 118948000 | C1477: 2025-11-13 00:00:00-05:00 | D1477: =LEFT(C1477,4) -> 2025 | E1477: =A1477*B1477 -> 4.7815905e+10
A1478: 404.35001 | B1478: 105506700 | C1478: 2025-11-14 00:00:00-05:00
A1479: 408.92001 | B1479: 102214300 | C1479: 2025-11-17 00:00:00-05:00
A1480: 401.25 | B1480: 80688600 | C1480: 2025-11-18 00:00:00-05:00
A1481: 403.98999 | B1481: 72047700 | C1481: 2025-11-19 00:00:00-05:00
A1482: 395.23001 | B1482: 113548800 | C1482: 2025-11-20 00:00:00-05:00
A1483: 391.09 | B1483: 100460600 | C1483: 2025-11-21 00:00:00-05:00
A1484: 417.78 | B1484: 96806400 | C1484: 2025-11-24 00:00:00-05:00
A1485: 419.39999 | B1485: 71915600 | C1485: 2025-11-25 00:00:00-05:00
A1486: 426.57999 | B1486: 63463000 | C1486: 2025-11-26 00:00:00-05:00
A1487: 430.17001 | B1487: 36252900 | C1487: 2025-11-28 00:00:00-05:00
A1488: 430.14001 | B1488: 57463600 | C1488: 2025-12-01 00:00:00-05:00
A1489: 429.23999 | B1489: 69336600 | C1489: 2025-12-02 00:00:00-05:00
... A1509: 449.72 | B1509: 49078000 | C1509: 2025-12-31 00:00:00-05:00

Sheet Volvo
A1: Close | B1: Volume | C1: date | D1: Year | E1: Close * Volume
A2: 65.199997 | B2: 70977504 | C2: 2021-10-29 00:00:00+02:00 | D2: =LEFT(C2,4) -> 2021 | E2: =A2*B2 -> 4.627733e+09
A3: 60.57 | B3: 20388814 | C3: 2021-11-01 00:00:00+01:00 | D3: =LEFT(C3,4) -> 2021 | E3: =A3*B3 -> 1.2349505e+09
A4: 57.990002 | B4: 14497507 | C4: 2021-11-02 00:00:00+01:00 | D4: =LEFT(C4,4) -> 2021 | E4: =A4*B4 -> 8.4071046e+08
A5: 58.880001 | B5: 7963166 | C5: 2021-11-03 00:00:00+01:00 | D5: =LEFT(C5,4) -> 2021 | E5: =A5*B5 -> 4.6887122e+08 | K5: Ср.Взвеш | L5: Прирост
A6: 59.080002 | B6: 2874916 | C6: 2021-11-04 00:00:00+01:00 | D6: =LEFT(C6,4) -> 2021 | E6: =A6*B6 -> 1.6985004e+08
A7: 59 | B7: 1228461 | C7: 2021-11-05 00:00:00+01:00 | D7: =LEFT(C7,4) -> 2021 | E7: =A7*B7 -> 72479199 | H7: 2020 | I7: =SUMIF(D:D,$H7,E:E) -> 0 | J7: =SUMIF($D:$D,$H7,B:B) -> 0 | K7: =I7/J7 -> #DIV/0!
A8: 57.18 | B8: 2989143 | C8: 2021-11-08 00:00:00+01:00 | D8: =LEFT(C8,4) -> 2021 | E8: =A8*B8 -> 1.709192e+08 | H8: 2021 | I8: =SUMIF(D:D,$H8,E:E) -> 1.7696736e+10 | J8: =SUMIF($D:$D,$H8,B:B) -> 254574268 | K8: =I8/J8 -> 69.515022 | L8: =(K8-K7)*100/K7 -> #DIV/0!
A9: 57.299999 | B9: 1889096 | C9: 2021-11-09 00:00:00+01:00 | D9: =LEFT(C9,4) -> 2021 | E9: =A9*B9 -> 1.082452e+08 | H9: 2022 | I9: =SUMIF(D:D,$H9,E:E) -> 5.6170514e+10 | J9: =SUMIF($D:$D,$H9,B:B) -> 848071330 | K9: =I9/J9 -> 66.233243 | L9: =(K9-K8)*100/K8 -> -4.720964
A10: 58.799999 | B10: 1866615 | C10: 2021-11-10 00:00:00+01:00 | D10: =LEFT(C10,4) -> 2021 | E10: =A10*B10 -> 1.0975696e+08 | H10: 2023 | I10: =SUMIF(D:D,$H10,E:E) -> 3.1671681e+10 | J10: =SUMIF($D:$D,$H10,B:B) -> 748458604 | K10: =I10/J10 -> 42.315875 | L10: =(K10-K9)*100/K9 -> -36.110821
A11: 64.599998 | B11: 7365218 | C11: 2021-11-11 00:00:00+01:00 | D11: =LEFT(C11,4) -> 2021 | E11: =A11*B11 -> 4.7579307e+08 | H11: 2024 | I11: =SUMIF(D:D,$H11,E:E) -> 4.3521141e+10 | J11: =SUMIF($D:$D,$H11,B:B) -> 1456682313 | K11: =I11/J11 -> 29.876892 | L11: =(K11-K10)*100/K10 -> -29.395547
A12: 76 | B12: 9951495 | C12: 2021-11-12 00:00:00+01:00 | D12: =LEFT(C12,4) -> 2021 | E12: =A12*B12 -> 756313620 | H12: 2025 | I12: =SUMIF(D:D,$H12,E:E) -> 3.4217655e+10 | J12: =SUMIF($D:$D,$H12,B:B) -> 1541307067 | K12: =I12/J12 -> 22.200414 | L12: =(K12-K11)*100/K11 -> -25.693696
A13: 80.239998 | B13: 10886284 | C13: 2021-11-15 00:00:00+01:00 | D13: =LEFT(C13,4) -> 2021 | E13: =A13*B13 -> 8.735154e+08
A14: 82.940002 | B14: 5705059 | C14: 2021-11-16 00:00:00+01:00 | D14: =LEFT(C14,4) -> 2021 | E14: =A14*B14 -> 4.7317761e+08
A15: 77 | B15: 7183513 | C15: 2021-11-17 00:00:00+01:00 | D15: =LEFT(C15,4) -> 2021 | E15: =A15*B15 -> 553130501
A16: 74.699997 | B16: 3367583 | C16: 2021-11-18 00:00:00+01:00 | D16: =LEFT(C16,4) -> 2021 | E16: =A16*B16 -> 2.5155844e+08
A17: 76.900002 | B17: 2674764 | C17: 2021-11-19 00:00:00+01:00 | D17: =LEFT(C17,4) -> 2021 | E17: =A17*B17 -> 2.0568936e+08
A18: 77.720001 | B18: 3161394 | C18: 2021-11-22 00:00:00+01:00 | D18: =LEFT(C18,4) -> 2021 | E18: =A18*B18 -> 2.4570355e+08
A19: 78.120003 | B19: 2333500 | C19: 2021-11-23 00:00:00+01:00 | D19: =LEFT(C19,4) -> 2021 | E19: =A19*B19 -> 1.8229303e+08
A20: 74.639999 | B20: 4239823 | C20: 2021-11-24 00:00:00+01:00 | D20: =LEFT(C20,4) -> 2021 | E20: =A20*B20 -> 3.1646039e+08
A21: 75.599998 | B21: 1259052 | C21: 2021-11-25 00:00:00+01:00 | D21: =LEFT(C21,4) -> 2021 | E21: =A21*B21 -> 95184329
A22: 70 | B22: 3222251 | C22: 2021-11-26 00:00:00+01:00 | D22: =LEFT(C22,4) -> 2021 | E22: =A22*B22 -> 225557570
A23: 68.5 | B23: 3754540 | C23: 2021-11-29 00:00:00+01:00 | D23: =LEFT(C23,4) -> 2021 | E23: =A23*B23 -> 257185990
A24: 77.82 | B24: 5823452 | C24: 2021-11-30 00:00:00+01:00 | D24: =LEFT(C24,4) -> 2021 | E24: =A24*B24 -> 4.5318103e+08
... A1049: 30.700001 | B1049: 2906883 | C1049: 2025-12-30 00:00:00+01:00 | D1049: =LEFT(C1049,4) -> 2025 | E1049: =A1049*B1049 -> 89241310
D1050: =LEFT(C1050,4) | E1050: =A1050*B1050 -> 0
D1051: =LEFT(C1051,4) | E1051: =A1051*B1051 -> 0
D1052: =LEFT(C1052,4) | E1052: =A1052*B1052 -> 0
D1053: =LEFT(C1053,4) | E1053: =A1053*B1053 -> 0
D1054: =LEFT(C1054,4) | E1054: =A1054*B1054 -> 0
D1055: =LEFT(C1055,4) | E1055: =A1055*B1055 -> 0
D1056: =LEFT(C1056,4) | E1056: =A1056*B1056 -> 0
D1057: =LEFT(C1057,4) | E1057: =A1057*B1057 -> 0
D1058: =LEFT(C1058,4) | E1058: =A1058*B1058 -> 0
D1059: =LEFT(C1059,4) | E1059: =A1059*B1059 -> 0
D1060: =LEFT(C1060,4) | E1060: =A1060*B1060 -> 0
D1061: =LEFT(C1061,4) | E1061: =A1061*B1061 -> 0
... D1477: =LEFT(C1477,4) | E1477: =A1477*B1477 -> 0

Sheet KIA
A1: Close | B1: Volume | C1: date | D1: Year | E1: Close * Volume
A2: 34068.219 | B2: 1355029 | C2: 2020-01-02 00:00:00+09:00 | D2: =LEFT(C2,4) -> 2020 | E2: =A2*B2 -> 4.6163424e+10
A3: 33667.418 | B3: 1569720 | C3: 2020-01-03 00:00:00+09:00 | D3: =LEFT(C3,4) -> 2020 | E3: =A3*B3 -> 5.2848419e+10
A4: 33587.254 | B4: 830880 | C4: 2020-01-06 00:00:00+09:00 | D4: =LEFT(C4,4) -> 2020 | E4: =A4*B4 -> 2.7906978e+10
A5: 33707.5 | B5: 1124218 | C5: 2020-01-07 00:00:00+09:00 | D5: =LEFT(C5,4) -> 2020 | E5: =A5*B5 -> 37894578235 | K5: Ср.Взвеш | L5: Прирост
A6: 33106.297 | B6: 997335 | C6: 2020-01-08 00:00:00+09:00 | D6: =LEFT(C6,4) -> 2020 | E6: =A6*B6 -> 3.3018069e+10
A7: 32665.41 | B7: 1908796 | C7: 2020-01-09 00:00:00+09:00 | D7: =LEFT(C7,4) -> 2020 | E7: =A7*B7 -> 6.2351604e+10 | H7: 2020 | I7: =SUMIF(D:D,$H7,E:E) -> 1.7487208e+13 | J7: =SUMIF($D:$D,$H7,B:B) -> 518196194 | K7: =I7/J7 -> 33746.307
A8: 32384.848 | B8: 1455064 | C8: 2020-01-10 00:00:00+09:00 | D8: =LEFT(C8,4) -> 2020 | E8: =A8*B8 -> 4.7122026e+10 | H8: 2021 | I8: =SUMIF(D:D,$H8,E:E) -> 5.5823133e+13 | J8: =SUMIF($D:$D,$H8,B:B) -> 812499743 | K8: =I8/J8 -> 68705.417 | L8: =(K8-K7)*100/K7 -> 103.59388
A9: 32424.93 | B9: 1299326 | C9: 2020-01-13 00:00:00+09:00 | D9: =LEFT(C9,4) -> 2020 | E9: =A9*B9 -> 4.2130554e+10 | H9: 2022 | I9: =SUMIF(D:D,$H9,E:E) -> 2.0379705e+13 | J9: =SUMIF($D:$D,$H9,B:B) -> 317667179 | K9: =I9/J9 -> 64154.266 | L9: =(K9-K8)*100/K8 -> -6.6241507
A10: 32986.055 | B10: 1412170 | C10: 2020-01-14 00:00:00+09:00 | D10: =LEFT(C10,4) -> 2020 | E10: =A10*B10 -> 4.6581917e+10 | H10: 2023 | I10: =SUMIF(D:D,$H10,E:E) -> 1.9374594e+13 | J10: =SUMIF($D:$D,$H10,B:B) -> 264145949 | K10: =I10/J10 -> 73348.064 | L10: =(K10-K9)*100/K9 -> 14.330766
A11: 33026.137 | B11: 920045 | C11: 2020-01-15 00:00:00+09:00 | D11: =LEFT(C11,4) -> 2020 | E11: =A11*B11 -> 3.0385532e+10 | H11: 2024 | I11: =SUMIF(D:D,$H11,E:E) -> 3.7536945e+13 | J11: =SUMIF($D:$D,$H11,B:B) -> 371918794 | K11: =I11/J11 -> 100927.8 | L11: =(K11-K10)*100/K10 -> 37.601176
A12: 32986.055 | B12: 1105472 | C12: 2020-01-16 00:00:00+09:00 | D12: =LEFT(C12,4) -> 2020 | E12: =A12*B12 -> 3.646516e+10 | H12: 2025 | I12: =SUMIF(D:D,$H12,E:E) -> 2.4969114e+13 | J12: =SUMIF($D:$D,$H12,B:B) -> 248997493 | K12: =I12/J12 -> 100278.58 | L12: =(K12-K11)*100/K11 -> -0.64325381
A13: 33186.453 | B13: 1016691 | C13: 2020-01-17 00:00:00+09:00 | D13: =LEFT(C13,4) -> 2020 | E13: =A13*B13 -> 3.3740368e+10
A14: 33346.781 | B14: 722748 | C14: 2020-01-20 00:00:00+09:00 | D14: =LEFT(C14,4) -> 2020 | E14: =A14*B14 -> 2.4101319e+10
A15: 33346.781 | B15: 567421 | C15: 2020-01-21 00:00:00+09:00 | D15: =LEFT(C15,4) -> 2020 | E15: =A15*B15 -> 1.8921664e+10
A16: 34148.383 | B16: 1435894 | C16: 2020-01-22 00:00:00+09:00 | D16: =LEFT(C16,4) -> 2020 | E16: =A16*B16 -> 4.9033458e+10
A17: 34789.668 | B17: 2060957 | C17: 2020-01-23 00:00:00+09:00 | D17: =LEFT(C17,4) -> 2020 | E17: =A17*B17 -> 7.170001e+10
A18: 34228.543 | B18: 1631227 | C18: 2020-01-28 00:00:00+09:00 | D18: =LEFT(C18,4) -> 2020 | E18: =A18*B18 -> 5.5834523e+10
A19: 34108.301 | B19: 1025015 | C19: 2020-01-29 00:00:00+09:00 | D19: =LEFT(C19,4) -> 2020 | E19: =A19*B19 -> 3.496152e+10
A20: 33627.336 | B20: 1030375 | C20: 2020-01-30 00:00:00+09:00 | D20: =LEFT(C20,4) -> 2020 | E20: =A20*B20 -> 3.4648766e+10
A21: 32785.652 | B21: 1349571 | C21: 2020-01-31 00:00:00+09:00 | D21: =LEFT(C21,4) -> 2020 | E21: =A21*B21 -> 4.4246566e+10
A22: 32144.369 | B22: 1428913 | C22: 2020-02-03 00:00:00+09:00 | D22: =LEFT(C22,4) -> 2020 | E22: =A22*B22 -> 4.5931507e+10
A23: 32264.611 | B23: 1122184 | C23: 2020-02-04 00:00:00+09:00 | D23: =LEFT(C23,4) -> 2020 | E23: =A23*B23 -> 3.6206831e+10
A24: 31583.244 | B24: 1554328 | C24: 2020-02-05 00:00:00+09:00 | D24: =LEFT(C24,4) -> 2020 | E24: =A24*B24 -> 4.9090721e+10
... A1471: 121800 | B1471: 435122 | C1471: 2025-12-30 00:00:00+09:00 | D1471: =LEFT(C1471,4) -> 2025 | E1471: =A1471*B1471 -> 52997859600
D1472: =LEFT(C1472,4) | E1472: =A1472*B1472 -> 0
D1473: =LEFT(C1473,4) | E1473: =A1473*B1473 -> 0
D1474: =LEFT(C1474,4) | E1474: =A1474*B1474 -> 0
D1475: =LEFT(C1475,4) | E1475: =A1475*B1475 -> 0
D1476: =LEFT(C1476,4) | E1476: =A1476*B1476 -> 0
D1477: =LEFT(C1477,4) | E1477: =A1477*B1477 -> 0

Sheet Toyota
A1: Close | B1: Volume | C1: date | D1: Year | E1: Close * Volume
A2: 1270.5012 | B2: 33361500 | C2: 2020-01-06 00:00:00+09:00 | D2: =LEFT(C2,4) -> 2020 | E2: =A2*B2 -> 4.2385826e+10
A3: 1295.6927 | B3: 24803500 | C3: 2020-01-07 00:00:00+09:00 | D3: =LEFT(C3,4) -> 2020 | E3: =A3*B3 -> 3.2137715e+10
A4: 1279.234 | B4: 28061000 | C4: 2020-01-08 00:00:00+09:00 | D4: =LEFT(C4,4) -> 2020 | E4: =A4*B4 -> 3.5896586e+10
A5: 1288.1351 | B5: 21265000 | C5: 2020-01-09 00:00:00+09:00 | D5: =LEFT(C5,4) -> 2020 | E5: =A5*B5 -> 2.7392194e+10 | K5: Ср.Взвеш | L5: Прирост
A6: 1286.6238 | B6: 17417000 | C6: 2020-01-10 00:00:00+09:00 | D6: =LEFT(C6,4) -> 2020 | E6: =A6*B6 -> 2.2409126e+10
A7: 1299.7235 | B7: 24309500 | C7: 2020-01-14 00:00:00+09:00 | D7: =LEFT(C7,4) -> 2020 | E7: =A7*B7 -> 3.1595629e+10 | H7: 2020 | I7: =SUMIF(D:D,$H7,E:E) -> 8.5236718e+12 | J7: =SUMIF($D:$D,$H7,B:B) -> 7162646000 | K7: =I7/J7 -> 1190.0172
A8: 1288.4709 | B8: 21778000 | C8: 2020-01-15 00:00:00+09:00 | D8: =LEFT(C8,4) -> 2020 | E8: =A8*B8 -> 2.806032e+10 | H8: 2021 | I8: =SUMIF(D:D,$H8,E:E) -> 1.1427951e+13 | J8: =SUMIF($D:$D,$H8,B:B) -> 7081485100 | K8: =I8/J8 -> 1613.7788 | L8: =(K8-K7)*100/K7 -> 35.609708
A9: 1290.9904 | B9: 16113000 | C9: 2020-01-16 00:00:00+09:00 | D9: =LEFT(C9,4) -> 2020 | E9: =A9*B9 -> 2.0801728e+10 | H9: 2022 | I9: =SUMIF(D:D,$H9,E:E) -> 1.237142e+13 | J9: =SUMIF($D:$D,$H9,B:B) -> 6544175100 | K9: =I9/J9 -> 1890.4476 | L9: =(K9-K8)*100/K8 -> 17.144157
A10: 1292.334 | B10: 21640000 | C10: 2020-01-17 00:00:00+09:00 | D10: =LEFT(C10,4) -> 2020 | E10: =A10*B10 -> 2.7966107e+10 | H10: 2023 | I10: =SUMIF(D:D,$H10,E:E) -> 1.4495889e+13 | J10: =SUMIF($D:$D,$H10,B:B) -> 6793752100 | K10: =I10/J10 -> 2133.7089 | L10: =(K10-K9)*100/K9 -> 12.86792
A11: 1306.6091 | B11: 15775000 | C11: 2020-01-20 00:00:00+09:00 | D11: =LEFT(C11,4) -> 2020 | E11: =A11*B11 -> 2.0611759e+10 | H11: 2024 | I11: =SUMIF(D:D,$H11,E:E) -> 2.1739444e+13 | J11: =SUMIF($D:$D,$H11,B:B) -> 7487314500 | K11: =I11/J11 -> 2903.5035 | L11: =(K11-K10)*100/K10 -> 36.077772
A12: 1319.0371 | B12: 25988000 | C12: 2020-01-21 00:00:00+09:00 | D12: =LEFT(C12,4) -> 2020 | E12: =A12*B12 -> 3.4279136e+10 | H12: 2025 | I12: =SUMIF(D:D,$H12,E:E) -> 1.8196513e+13 | J12: =SUMIF($D:$D,$H12,B:B) -> 6583111100 | K12: =I12/J12 -> 2764.1206 | L12: =(K12-K11)*100/K11 -> -4.8005083
A13: 1313.8308 | B13: 22193000 | C13: 2020-01-22 00:00:00+09:00 | D13: =LEFT(C13,4) -> 2020 | E13: =A13*B13 -> 2.9157847e+10
A14: 1316.014 | B14: 20944000 | C14: 2020-01-23 00:00:00+09:00 | D14: =LEFT(C14,4) -> 2020 | E14: =A14*B14 -> 2.7562598e+10
A15: 1322.0601 | B15: 18572500 | C15: 2020-01-24 00:00:00+09:00 | D15: =LEFT(C15,4) -> 2020 | E15: =A15*B15 -> 2.455396e+10
A16: 1301.9066 | B16: 24639500 | C16: 2020-01-27 00:00:00+09:00 | D16: =LEFT(C16,4) -> 2020 | E16: =A16*B16 -> 3.2078328e+10
A17: 1301.067 | B17: 24655000 | C17: 2020-01-28 00:00:00+09:00 | D17: =LEFT(C17,4) -> 2020 | E17: =A17*B17 -> 3.2077807e+10
A18: 1304.2581 | B18: 17979500 | C18: 2020-01-29 00:00:00+09:00 | D18: =LEFT(C18,4) -> 2020 | E18: =A18*B18 -> 2.3449908e+10
A19: 1282.0895 | B19: 24394000 | C19: 2020-01-30 00:00:00+09:00 | D19: =LEFT(C19,4) -> 2020 | E19: =A19*B19 -> 3.1275291e+10
A20: 1285.1121 | B20: 24543500 | C20: 2020-01-31 00:00:00+09:00 | D20: =LEFT(C20,4) -> 2020 | E20: =A20*B20 -> 3.1541148e+10
A21: 1273.0203 | B21: 23018000 | C21: 2020-02-03 00:00:00+09:00 | D21: =LEFT(C21,4) -> 2020 | E21: =A21*B21 -> 2.930238e+10
A22: 1282.929 | B22: 19983000 | C22: 2020-02-04 00:00:00+09:00 | D22: =LEFT(C22,4) -> 2020 | E22: =A22*B22 -> 2.5636769e+10
A23: 1295.6927 | B23: 20036000 | C23: 2020-02-05 00:00:00+09:00 | D23: =LEFT(C23,4) -> 2020 | E23: =A23*B23 -> 2.59605e+10
A24: 1329.1136 | B24: 63677500 | C24: 2020-02-06 00:00:00+09:00 | D24: =LEFT(C24,4) -> 2020 | E24: =A24*B24 -> 8.4634634e+10
... A1466: 3356 | B1466: 12175900 | C1466: 2025-12-30 00:00:00+09:00 | D1466: =LEFT(C1466,4) -> 2025 | E1466: =A1466*B1466 -> 40862320400
D1467: =LEFT(C1467,4) | E1467: =A1467*B1467 -> 0
D1468: =LEFT(C1468,4) | E1468: =A1468*B1468 -> 0
D1469: =LEFT(C1469,4) | E1469: =A1469*B1469 -> 0
D1470: =LEFT(C1470,4) | E1470: =A1470*B1470 -> 0
D1471: =LEFT(C1471,4) | E1471: =A1471*B1471 -> 0
D1472: =LEFT(C1472,4) | E1472: =A1472*B1472 -> 0
D1473: =LEFT(C1473,4) | E1473: =A1473*B1473 -> 0
D1474: =LEFT(C1474,4) | E1474: =A1474*B1474 -> 0
D1475: =LEFT(C1475,4) | E1475: =A1475*B1475 -> 0
D1476: =LEFT(C1476,4) | E1476: =A1476*B1476 -> 0
D1477: =LEFT(C1477,4) | E1477: =A1477*B1477 -> 0

Sheet Hyndai
A1: Close | B1: Volume | C1: date | D1: Year | E1: Close * Volume
A2: 94578.555 | B2: 556532 | C2: 2020-01-02 00:00:00+09:00 | D2: =LEFT(C2,4) -> 2020 | E2: =A2*B2 -> 5.2635992e+10
A3: 92975.523 | B3: 1145187 | C3: 2020-01-03 00:00:00+09:00 | D3: =LEFT(C3,4) -> 2020 | E3: =A3*B3 -> 1.0647436e+11
A4: 92975.523 | B4: 334574 | C4: 2020-01-06 00:00:00+09:00 | D4: =LEFT(C4,4) -> 2020 | E4: =A4*B4 -> 3.1107193e+10
A5: 92574.766 | B5: 674196 | C5: 2020-01-07 00:00:00+09:00 | D5: =LEFT(C5,4) -> 2020 | E5: =A5*B5 -> 6.2413537e+10 | K5: Ср.Взвеш | L5: Прирост
A6: 89769.477 | B6: 1044825 | C6: 2020-01-08 00:00:00+09:00 | D6: =LEFT(C6,4) -> 2020 | E6: =A6*B6 -> 9.3793393e+10
A7: 89368.734 | B7: 1375510 | C7: 2020-01-09 00:00:00+09:00 | D7: =LEFT(C7,4) -> 2020 | E7: =A7*B7 -> 1.2292759e+11 | H7: 2020 | I7: =SUMIF(D:D,$H7,E:E) -> 5.6160764e+13 | J7: =SUMIF($D:$D,$H7,B:B) -> 502717464 | K7: =I7/J7 -> 111714.37
A8: 90971.75 | B8: 896507 | C8: 2020-01-10 00:00:00+09:00 | D8: =LEFT(C8,4) -> 2020 | E8: =A8*B8 -> 8.1556811e+10 | H8: 2021 | I8: =SUMIF(D:D,$H8,E:E) -> 5.7250076e+13 | J8: =SUMIF($D:$D,$H8,B:B) -> 302742976 | K8: =I8/J8 -> 189104.56 | L8: =(K8-K7)*100/K7 -> 69.275054
A9: 92174.023 | B9: 692917 | C9: 2020-01-13 00:00:00+09:00 | D9: =LEFT(C9,4) -> 2020 | E9: =A9*B9 -> 6.3868948e+10 | H9: 2022 | I9: =SUMIF(D:D,$H9,E:E) -> 2.6712385e+13 | J9: =SUMIF($D:$D,$H9,B:B) -> 176472701 | K9: =I9/J9 -> 151368.37 | L9: =(K9-K8)*100/K8 -> -19.955196
A10: 92975.523 | B10: 739959 | C10: 2020-01-14 00:00:00+09:00 | D10: =LEFT(C10,4) -> 2020 | E10: =A10*B10 -> 6.8798075e+10 | H10: 2023 | I10: =SUMIF(D:D,$H10,E:E) -> 1.9903502e+13 | J10: =SUMIF($D:$D,$H10,B:B) -> 119617224 | K10: =I10/J10 -> 166393.28 | L10: =(K10-K9)*100/K9 -> 9.926052
A11: 92174.023 | B11: 564142 | C11: 2020-01-15 00:00:00+09:00 | D11: =LEFT(C11,4) -> 2020 | E11: =A11*B11 -> 5.1999238e+10 | H11: 2024 | I11: =SUMIF(D:D,$H11,E:E) -> 5.1741353e+13 | J11: =SUMIF($D:$D,$H11,B:B) -> 233694250 | K11: =I11/J11 -> 221406.19 | L11: =(K11-K10)*100/K10 -> 33.06198
A12: 94979.32 | B12: 1638719 | C12: 2020-01-16 00:00:00+09:00 | D12: =LEFT(C12,4) -> 2020 | E12: =A12*B12 -> 1.5564442e+11 | H12: 2025 | I12: =SUMIF(D:D,$H12,E:E) -> 4.2214936e+13 | J12: =SUMIF($D:$D,$H12,B:B) -> 190502265 | K12: =I12/J12 -> 221598.08 | L12: =(K12-K11)*100/K11 -> 0.086668969
A13: 94979.32 | B13: 574301 | C13: 2020-01-17 00:00:00+09:00 | D13: =LEFT(C13,4) -> 2020 | E13: =A13*B13 -> 5.4546719e+10
A14: 94578.555 | B14: 445922 | C14: 2020-01-20 00:00:00+09:00 | D14: =LEFT(C14,4) -> 2020 | E14: =A14*B14 -> 4.2174658e+10
A15: 93777.039 | B15: 545156 | C15: 2020-01-21 00:00:00+09:00 | D15: =LEFT(C15,4) -> 2020 | E15: =A15*B15 -> 5.1123116e+10
A16: 101792.18 | B16: 2773421 | C16: 2020-01-22 00:00:00+09:00 | D16: =LEFT(C16,4) -> 2020 | E16: =A16*B16 -> 2.8231257e+11
A17: 104597.46 | B17: 2492785 | C17: 2020-01-23 00:00:00+09:00 | D17: =LEFT(C17,4) -> 2020 | E17: =A17*B17 -> 2.6073898e+11
A18: 104998.23 | B18: 1841752 | C18: 2020-01-28 00:00:00+09:00 | D18: =LEFT(C18,4) -> 2020 | E18: =A18*B18 -> 1.9338071e+11
A19: 104998.23 | B19: 1318578 | C19: 2020-01-29 00:00:00+09:00 | D19: =LEFT(C19,4) -> 2020 | E19: =A19*B19 -> 1.3844836e+11
A20: 102192.92 | B20: 1034661 | C20: 2020-01-30 00:00:00+09:00 | D20: =LEFT(C20,4) -> 2020 | E20: =A20*B20 -> 1.0573503e+11
A21: 100189.15 | B21: 1035126 | C21: 2020-01-31 00:00:00+09:00 | D21: =LEFT(C21,4) -> 2020 | E21: =A21*B21 -> 1.0370839e+11
A22: 98986.883 | B22: 1270442 | C22: 2020-02-03 00:00:00+09:00 | D22: =LEFT(C22,4) -> 2020 | E22: =A22*B22 -> 1.2575709e+11
A23: 99387.633 | B23: 1203992 | C23: 2020-02-04 00:00:00+09:00 | D23: =LEFT(C23,4) -> 2020 | E23: =A23*B23 -> 1.1966191e+11
A24: 99387.633 | B24: 1032267 | C24: 2020-02-05 00:00:00+09:00 | D24: =LEFT(C24,4) -> 2020 | E24: =A24*B24 -> 1.0259457e+11
... A1471: 296500 | B1471: 628188 | C1471: 2025-12-30 00:00:00+09:00 | D1471: =LEFT(C1471,4) -> 2025 | E1471: =A1471*B1471 -> 186257742000
D1472: =LEFT(C1472,4) | E1472: =A1472*B1472 -> 0
D1473: =LEFT(C1473,4) | E1473: =A1473*B1473 -> 0
D1474: =LEFT(C1474,4) | E1474: =A1474*B1474 -> 0
D1475: =LEFT(C1475,4) | E1475: =A1475*B1475 -> 0
D1476: =LEFT(C1476,4) | E1476: =A1476*B1476 -> 0
D1477: =LEFT(C1477,4) | E1477: =A1477*B1477 -> 0

Sheet Volkswagen
A1: Close | B1: Volume | C1: date | D1: Year | E1: Close * Volume
A2: 112.09666 | B2: 814205 | C2: 2020-01-02 00:00:00+01:00 | D2: =LEFT(C2,4) -> 2020 | E2: =A2*B2 -> 91269658
A3: 109.69943 | B3: 948457 | C3: 2020-01-03 00:00:00+01:00 | D3: =LEFT(C3,4) -> 2020 | E3: =A3*B3 -> 1.0404519e+08
A4: 109.687 | B4: 658053 | C4: 2020-01-06 00:00:00+01:00 | D4: =LEFT(C4,4) -> 2020 | E4: =A4*B4 -> 72179862
A5: 109.33923 | B5: 932694 | C5: 2020-01-07 00:00:00+01:00 | D5: =LEFT(C5,4) -> 2020 | E5: =A5*B5 -> 1.0198004e+08 | K5: Ср.Взвеш | L5: Прирост
A6: 109.81123 | B6: 840853 | C6: 2020-01-08 00:00:00+01:00 | D6: =LEFT(C6,4) -> 2020 | E6: =A6*B6 -> 92335105
A7: 112.85431 | B7: 1338153 | C7: 2020-01-09 00:00:00+01:00 | D7: =LEFT(C7,4) -> 2020 | E7: =A7*B7 -> 1.5101633e+08 | H7: 2020 | I7: =SUMIF(D:D,$H7,E:E) -> 3.1172568e+10 | J7: =SUMIF($D:$D,$H7,B:B) -> 361230347 | K7: =I7/J7 -> 86.295541
A8: 115.21421 | B8: 1518740 | C8: 2020-01-10 00:00:00+01:00 | D8: =LEFT(C8,4) -> 2020 | E8: =A8*B8 -> 1.7498043e+08 | H8: 2021 | I8: =SUMIF(D:D,$H8,E:E) -> 3.7735539e+10 | J8: =SUMIF($D:$D,$H8,B:B) -> 296806816 | K8: =I8/J8 -> 127.13839 | L8: =(K8-K7)*100/K7 -> 47.329033
A9: 115.06518 | B9: 812123 | C9: 2020-01-13 00:00:00+01:00 | D9: =LEFT(C9,4) -> 2020 | E9: =A9*B9 -> 93447077 | H9: 2022 | I9: =SUMIF(D:D,$H9,E:E) -> 2.97301e+10 | J9: =SUMIF($D:$D,$H9,B:B) -> 293819336 | K9: =I9/J9 -> 101.18497 | L9: =(K9-K8)*100/K8 -> -20.413519
A10: 115.02792 | B10: 767691 | C10: 2020-01-14 00:00:00+01:00 | D10: =LEFT(C10,4) -> 2020 | E10: =A10*B10 -> 88305896 | H10: 2023 | I10: =SUMIF(D:D,$H10,E:E) -> 2.6396141e+10 | J10: =SUMIF($D:$D,$H10,B:B) -> 262196377 | K10: =I10/J10 -> 100.67317 | L10: =(K10-K9)*100/K9 -> -0.50580324
A11: 113.41322 | B11: 1068497 | C11: 2020-01-15 00:00:00+01:00 | D11: =LEFT(C11,4) -> 2020 | E11: =A11*B11 -> 1.2118169e+08 | H11: 2024 | I11: =SUMIF(D:D,$H11,E:E) -> 2.4417236e+10 | J11: =SUMIF($D:$D,$H11,B:B) -> 256307442 | K11: =I11/J11 -> 95.26542 | L11: =(K11-K10)*100/K10 -> -5.3715901
A12: 111.73641 | B12: 925738 | C12: 2020-01-16 00:00:00+01:00 | D12: =LEFT(C12,4) -> 2020 | E12: =A12*B12 -> 1.0343864e+08 | H12: 2025 | I12: =SUMIF(D:D,$H12,E:E) -> 2.0183738e+10 | J12: =SUMIF($D:$D,$H12,B:B) -> 216940103 | K12: =I12/J12 -> 93.038297 | L12: =(K12-K11)*100/K11 -> -2.3378085
A13: 112.63071 | B13: 988847 | C13: 2020-01-17 00:00:00+01:00 | D13: =LEFT(C13,4) -> 2020 | E13: =A13*B13 -> 1.1137454e+08
A14: 113.04062 | B14: 422072 | C14: 2020-01-20 00:00:00+01:00 | D14: =LEFT(C14,4) -> 2020 | E14: =A14*B14 -> 47711280
A15: 112.59345 | B15: 649325 | C15: 2020-01-21 00:00:00+01:00 | D15: =LEFT(C15,4) -> 2020 | E15: =A15*B15 -> 73109744
A16: 111.25203 | B16: 1049016 | C16: 2020-01-22 00:00:00+01:00 | D16: =LEFT(C16,4) -> 2020 | E16: =A16*B16 -> 1.1670516e+08
A17: 109.66219 | B17: 837482 | C17: 2020-01-23 00:00:00+01:00 | D17: =LEFT(C17,4) -> 2020 | E17: =A17*B17 -> 91840107
A18: 110.24596 | B18: 895854 | C18: 2020-01-24 00:00:00+01:00 | D18: =LEFT(C18,4) -> 2020 | E18: =A18*B18 -> 98764281
A19: 106.59429 | B19: 1356742 | C19: 2020-01-27 00:00:00+01:00 | D19: =LEFT(C19,4) -> 2020 | E19: =A19*B19 -> 1.4462095e+08
A20: 107.10352 | B20: 985026 | C20: 2020-01-28 00:00:00+01:00 | D20: =LEFT(C20,4) -> 2020 | E20: =A20*B20 -> 1.0549975e+08
A21: 105.52608 | B21: 907400 | C21: 2020-01-29 00:00:00+01:00 | D21: =LEFT(C21,4) -> 2020 | E21: =A21*B21 -> 95754363
A22: 101.84957 | B22: 1649026 | C22: 2020-01-30 00:00:00+01:00 | D22: =LEFT(C22,4) -> 2020 | E22: =A22*B22 -> 1.6795259e+08
A23: 100.84351 | B23: 1425734 | C23: 2020-01-31 00:00:00+01:00 | D23: =LEFT(C23,4) -> 2020 | E23: =A23*B23 -> 1.4377601e+08
A24: 101.10434 | B24: 858700 | C24: 2020-02-03 00:00:00+01:00 | D24: =LEFT(C24,4) -> 2020 | E24: =A24*B24 -> 86818296
... A1477: 90.080002 | B1477: 832970 | C1477: 2025-10-14 00:00:00+02:00 | D1477: =LEFT(C1477,4) -> 2025 | E1477: =A1477*B1477 -> 75033939
A1478: 90.199997 | B1478: 580308 | C1478: 2025-10-15 00:00:00+02:00
A1479: 89.940002 | B1479: 718718 | C1479: 2025-10-16 00:00:00+02:00
A1480: 91.199997 | B1480: 1318044 | C1480: 2025-10-17 00:00:00+02:00
A1481: 91.620003 | B1481: 597985 | C1481: 2025-10-20 00:00:00+02:00
A1482: 91.300003 | B1482: 1048072 | C1482: 2025-10-21 00:00:00+02:00
A1483: 89.300003 | B1483: 1127069 | C1483: 2025-10-22 00:00:00+02:00
A1484: 89.360001 | B1484: 1009971 | C1484: 2025-10-23 00:00:00+02:00
A1485: 90.519997 | B1485: 739697 | C1485: 2025-10-24 00:00:00+02:00
A1486: 91.360001 | B1486: 766519 | C1486: 2025-10-27 00:00:00+01:00
A1487: 91.440002 | B1487: 597573 | C1487: 2025-10-28 00:00:00+01:00
A1488: 92 | B1488: 1182664 | C1488: 2025-10-29 00:00:00+01:00
A1489: 90.239998 | B1489: 1327554 | C1489: 2025-10-30 00:00:00+01:00
... A1529: 103.55 | B1529: 374985 | C1529: 2025-12-30 00:00:00+01:00

Sheet BMW
A1: Close | B1: Volume | C1: date | D1: Year | E1: Close * Volume
A2: 52.578621 | B2: 1232319 | C2: 2020-01-02 00:00:00+01:00 | D2: =LEFT(C2,4) -> 2020 | E2: =A2*B2 -> 64793634
A3: 51.941051 | B3: 1153245 | C3: 2020-01-03 00:00:00+01:00 | D3: =LEFT(C3,4) -> 2020 | E3: =A3*B3 -> 59900758
A4: 51.749775 | B4: 1039192 | C4: 2020-01-06 00:00:00+01:00 | D4: =LEFT(C4,4) -> 2020 | E4: =A4*B4 -> 53777952
A5: 52.578621 | B5: 1302124 | C5: 2020-01-07 00:00:00+01:00 | D5: =LEFT(C5,4) -> 2020 | E5: =A5*B5 -> 68463884 | K5: Ср.Взвеш | L5: Прирост
A6: 52.713219 | B6: 941807 | C6: 2020-01-08 00:00:00+01:00 | D6: =LEFT(C6,4) -> 2020 | E6: =A6*B6 -> 49645678
A7: 52.677803 | B7: 1391131 | C7: 2020-01-09 00:00:00+01:00 | D7: =LEFT(C7,4) -> 2020 | E7: =A7*B7 -> 73281725 | H7: 2020 | I7: =SUMIF(D:D,$H7,E:E) -> 2.2117865e+10 | J7: =SUMIF($D:$D,$H7,B:B) -> 521694908 | K7: =I7/J7 -> 42.396168
A8: 52.826569 | B8: 1102138 | C8: 2020-01-10 00:00:00+01:00 | D8: =LEFT(C8,4) -> 2020 | E8: =A8*B8 -> 58222169 | H8: 2021 | I8: =SUMIF(D:D,$H8,E:E) -> 2.1311581e+10 | J8: =SUMIF($D:$D,$H8,B:B) -> 340004577 | K8: =I8/J8 -> 62.680277 | L8: =(K8-K7)*100/K7 -> 47.844203
A9: 52.16066 | B9: 884147 | C9: 2020-01-13 00:00:00+01:00 | D9: =LEFT(C9,4) -> 2020 | E9: =A9*B9 -> 46117691 | H9: 2022 | I9: =SUMIF(D:D,$H9,E:E) -> 2.3202193e+10 | J9: =SUMIF($D:$D,$H9,B:B) -> 363462059 | K9: =I9/J9 -> 63.83663 | L9: =(K9-K8)*100/K8 -> 1.8448434
A10: 51.926884 | B10: 979352 | C10: 2020-01-14 00:00:00+01:00 | D10: =LEFT(C10,4) -> 2020 | E10: =A10*B10 -> 50854697 | H10: 2023 | I10: =SUMIF(D:D,$H10,E:E) -> 2.2584386e+10 | J10: =SUMIF($D:$D,$H10,B:B) -> 262621082 | K10: =I10/J10 -> 85.996091 | L10: =(K10-K9)*100/K9 -> 34.712768
A11: 51.140541 | B11: 1607651 | C11: 2020-01-15 00:00:00+01:00 | D11: =LEFT(C11,4) -> 2020 | E11: =A11*B11 -> 82216142 | H11: 2024 | I11: =SUMIF(D:D,$H11,E:E) -> 2.2480642e+10 | J11: =SUMIF($D:$D,$H11,B:B) -> 275930202 | K11: =I11/J11 -> 81.472207 | L11: =(K11-K10)*100/K10 -> -5.2605693
A12: 50.41795 | B12: 1730300 | C12: 2020-01-16 00:00:00+01:00 | D12: =LEFT(C12,4) -> 2020 | E12: =A12*B12 -> 87238178 | H12: 2025 | I12: =SUMIF(D:D,$H12,E:E) -> 1.8126889e+10 | J12: =SUMIF($D:$D,$H12,B:B) -> 234253671 | K12: =I12/J12 -> 77.381451 | L12: =(K12-K11)*100/K11 -> -5.0210448
A13: 50.340031 | B13: 2112839 | C13: 2020-01-17 00:00:00+01:00 | D13: =LEFT(C13,4) -> 2020 | E13: =A13*B13 -> 1.0636038e+08
A14: 50.750912 | B14: 837922 | C14: 2020-01-20 00:00:00+01:00 | D14: =LEFT(C14,4) -> 2020 | E14: =A14*B14 -> 42525305
A15: 50.587978 | B15: 888947 | C15: 2020-01-21 00:00:00+01:00 | D15: =LEFT(C15,4) -> 2020 | E15: =A15*B15 -> 44970032
A16: 50.262104 | B16: 1755064 | C16: 2020-01-22 00:00:00+01:00 | D16: =LEFT(C16,4) -> 2020 | E16: =A16*B16 -> 88213209
A17: 49.369503 | B17: 1472242 | C17: 2020-01-23 00:00:00+01:00 | D17: =LEFT(C17,4) -> 2020 | E17: =A17*B17 -> 72683856
A18: 49.171146 | B18: 1281775 | C18: 2020-01-24 00:00:00+01:00 | D18: =LEFT(C18,4) -> 2020 | E18: =A18*B18 -> 63026346
A19: 47.959747 | B19: 1828640 | C19: 2020-01-27 00:00:00+01:00 | D19: =LEFT(C19,4) -> 2020 | E19: =A19*B19 -> 87701112
A20: 47.336346 | B20: 2112085 | C20: 2020-01-28 00:00:00+01:00 | D20: =LEFT(C20,4) -> 2020 | E20: =A20*B20 -> 99978386
A21: 47.145081 | B21: 1456090 | C21: 2020-01-29 00:00:00+01:00 | D21: =LEFT(C21,4) -> 2020 | E21: =A21*B21 -> 68647480
A22: 46.443741 | B22: 1995833 | C22: 2020-01-30 00:00:00+01:00 | D22: =LEFT(C22,4) -> 2020 | E22: =A22*B22 -> 92693951
A23: 45.579468 | B23: 2069682 | C23: 2020-01-31 00:00:00+01:00 | D23: =LEFT(C23,4) -> 2020 | E23: =A23*B23 -> 94335004
A24: 45.607811 | B24: 1818370 | C24: 2020-02-03 00:00:00+01:00 | D24: =LEFT(C24,4) -> 2020 | E24: =A24*B24 -> 82931875
... A1477: 78.599998 | B1477: 761475 | C1477: 2025-10-14 00:00:00+02:00 | D1477: =LEFT(C1477,4) -> 2025 | E1477: =A1477*B1477 -> 59851934
A1478: 78.879997 | B1478: 826764 | C1478: 2025-10-15 00:00:00+02:00
A1479: 79.580002 | B1479: 718471 | C1479: 2025-10-16 00:00:00+02:00
A1480: 80.220001 | B1480: 919050 | C1480: 2025-10-17 00:00:00+02:00
A1481: 81.160004 | B1481: 729155 | C1481: 2025-10-20 00:00:00+02:00
A1482: 81.440002 | B1482: 1201468 | C1482: 2025-10-21 00:00:00+02:00
A1483: 80.480003 | B1483: 1631085 | C1483: 2025-10-22 00:00:00+02:00
A1484: 80.379997 | B1484: 712564 | C1484: 2025-10-23 00:00:00+02:00
A1485: 81.160004 | B1485: 692084 | C1485: 2025-10-24 00:00:00+02:00
A1486: 81.519997 | B1486: 520818 | C1486: 2025-10-27 00:00:00+01:00
A1487: 81.239998 | B1487: 689596 | C1487: 2025-10-28 00:00:00+01:00
A1488: 82.099998 | B1488: 869500 | C1488: 2025-10-29 00:00:00+01:00
A1489: 81.379997 | B1489: 917543 | C1489: 2025-10-30 00:00:00+01:00
... A1529: 93.139999 | B1529: 286069 | C1529: 2025-12-30 00:00:00+01:00

Sheet AITO(Seres)
A1: Close | B1: Volume | C1: date | D1: Year | E1: Close * Volume
A2: 131.5 | B2: 18589510 | C2: 2025-11-05 00:00:00+08:00 | D2: =LEFT(C2,4) -> 2025 | E2: =A2*B2 -> 2444520565
A3: 123.9 | B3: 4528444 | C3: 2025-11-06 00:00:00+08:00 | D3: =LEFT(C3,4) -> 2025 | E3: =A3*B3 -> 5.6107422e+08
A4: 114 | B4: 6713686 | C4: 2025-11-07 00:00:00+08:00 | D4: =LEFT(C4,4) -> 2025 | E4: =A4*B4 -> 765360204
A5: 115.6 | B5: 2025940 | C5: 2025-11-10 00:00:00+08:00 | D5: =LEFT(C5,4) -> 2025 | E5: =A5*B5 -> 2.3419866e+08 | K5: Ср.Взвеш | L5: Прирост
A6: 110 | B6: 2154834 | C6: 2025-11-11 00:00:00+08:00 | D6: =LEFT(C6,4) -> 2025 | E6: =A6*B6 -> 237031740
A7: 115.5 | B7: 1766003 | C7: 2025-11-12 00:00:00+08:00 | D7: =LEFT(C7,4) -> 2025 | E7: =A7*B7 -> 2.0397335e+08 | H7: 2020 | I7: =SUMIF(D:D,$H7,E:E) -> 0 | J7: =SUMIF($D:$D,$H7,B:B) -> 0 | K7: =I7/J7 -> #DIV/0!
A8: 119.6 | B8: 1499400 | C8: 2025-11-13 00:00:00+08:00 | D8: =LEFT(C8,4) -> 2025 | E8: =A8*B8 -> 1.7932824e+08 | H8: 2021 | I8: =SUMIF(D:D,$H8,E:E) -> 0 | J8: =SUMIF($D:$D,$H8,B:B) -> 0 | K8: =I8/J8 -> #DIV/0! | L8: =(K8-K7)*100/K7 -> #DIV/0!
A9: 120.3 | B9: 1248072 | C9: 2025-11-14 00:00:00+08:00 | D9: =LEFT(C9,4) -> 2025 | E9: =A9*B9 -> 1.5014307e+08 | H9: 2022 | I9: =SUMIF(D:D,$H9,E:E) -> 0 | J9: =SUMIF($D:$D,$H9,B:B) -> 0 | K9: =I9/J9 -> #DIV/0! | L9: =(K9-K8)*100/K8 -> #DIV/0!
A10: 120.1 | B10: 1146369 | C10: 2025-11-17 00:00:00+08:00 | D10: =LEFT(C10,4) -> 2025 | E10: =A10*B10 -> 1.3767892e+08 | H10: 2023 | I10: =SUMIF(D:D,$H10,E:E) -> 0 | J10: =SUMIF($D:$D,$H10,B:B) -> 0 | K10: =I10/J10 -> #DIV/0! | L10: =(K10-K9)*100/K9 -> #DIV/0!
A11: 114.7 | B11: 518038 | C11: 2025-11-18 00:00:00+08:00 | D11: =LEFT(C11,4) -> 2025 | E11: =A11*B11 -> 59418957 | H11: 2024 | I11: =SUMIF(D:D,$H11,E:E) -> 0 | J11: =SUMIF($D:$D,$H11,B:B) -> 0 | K11: =I11/J11 -> #DIV/0! | L11: =(K11-K10)*100/K10 -> #DIV/0!
A12: 116.7 | B12: 1039200 | C12: 2025-11-19 00:00:00+08:00 | D12: =LEFT(C12,4) -> 2025 | E12: =A12*B12 -> 1.2127464e+08 | H12: 2025 | I12: =SUMIF(D:D,$H12,E:E) -> 8.7918378e+09 | J12: =SUMIF($D:$D,$H12,B:B) -> 73807225 | K12: =I12/J12 -> 119.11893 | L12: =(K12-K11)*100/K11 -> #DIV/0!
A13: 115.2 | B13: 1160700 | C13: 2025-11-20 00:00:00+08:00 | D13: =LEFT(C13,4) -> 2025 | E13: =A13*B13 -> 1.3371264e+08
A14: 109.5 | B14: 1237260 | C14: 2025-11-21 00:00:00+08:00 | D14: =LEFT(C14,4) -> 2025 | E14: =A14*B14 -> 135479970
A15: 110.2 | B15: 1143039 | C15: 2025-11-24 00:00:00+08:00 | D15: =LEFT(C15,4) -> 2025 | E15: =A15*B15 -> 1.2596289e+08
A16: 114.4 | B16: 1337746 | C16: 2025-11-25 00:00:00+08:00 | D16: =LEFT(C16,4) -> 2025 | E16: =A16*B16 -> 1.5303814e+08
A17: 114 | B17: 1090659 | C17: 2025-11-26 00:00:00+08:00 | D17: =LEFT(C17,4) -> 2025 | E17: =A17*B17 -> 124335126
A18: 125.2 | B18: 2166460 | C18: 2025-11-27 00:00:00+08:00 | D18: =LEFT(C18,4) -> 2025 | E18: =A18*B18 -> 2.7124079e+08
A19: 115 | B19: 1527375 | C19: 2025-11-28 00:00:00+08:00 | D19: =LEFT(C19,4) -> 2025 | E19: =A19*B19 -> 175648125
A20: 121 | B20: 4353934 | C20: 2025-12-01 00:00:00+08:00 | D20: =LEFT(C20,4) -> 2025 | E20: =A20*B20 -> 526826014
A21: 117.2 | B21: 1382139 | C21: 2025-12-02 00:00:00+08:00 | D21: =LEFT(C21,4) -> 2025 | E21: =A21*B21 -> 1.6198669e+08
A22: 116.5 | B22: 750800 | C22: 2025-12-03 00:00:00+08:00 | D22: =LEFT(C22,4) -> 2025 | E22: =A22*B22 -> 87468200
A23: 115.8 | B23: 705611 | C23: 2025-12-04 00:00:00+08:00 | D23: =LEFT(C23,4) -> 2025 | E23: =A23*B23 -> 81709756
A24: 114.6 | B24: 1114374 | C24: 2025-12-05 00:00:00+08:00 | D24: =LEFT(C24,4) -> 2025 | E24: =A24*B24 -> 1.2770726e+08
... A40: 107.5 | B40: 0 | C40: 2025-12-31 00:00:00+08:00 | D40: =LEFT(C40,4) -> 2025 | E40: =A40*B40 -> 0
D41: =LEFT(C41,4) | E41: =A41*B41 -> 0
D42: =LEFT(C42,4) | E42: =A42*B42 -> 0
D43: =LEFT(C43,4) | E43: =A43*B43 -> 0
D44: =LEFT(C44,4) | E44: =A44*B44 -> 0
D45: =LEFT(C45,4) | E45: =A45*B45 -> 0
D46: =LEFT(C46,4) | E46: =A46*B46 -> 0
D47: =LEFT(C47,4) | E47: =A47*B47 -> 0
D48: =LEFT(C48,4) | E48: =A48*B48 -> 0
D49: =LEFT(C49,4) | E49: =A49*B49 -> 0
D50: =LEFT(C50,4) | E50: =A50*B50 -> 0
D51: =LEFT(C51,4) | E51: =A51*B51 -> 0
D52: =LEFT(C52,4) | E52: =A52*B52 -> 0
... D1477: =LEFT(C1477,4) | E1477: =A1477*B1477 -> 0

Sheet Aion(GAC)
A1: Close | B1: Volume | C1: date | D1: Year | E1: Close * Volume
A2: 7.9484043 | B2: 32569357 | C2: 2020-01-02 00:00:00+08:00 | D2: =LEFT(C2,4) -> 2020 | E2: =A2*B2 -> 2.5887442e+08
A3: 7.9564815 | B3: 27981600 | C3: 2020-01-03 00:00:00+08:00 | D3: =LEFT(C3,4) -> 2020 | E3: =A3*B3 -> 2.2263508e+08
A4: 7.9160933 | B4: 22479585 | C4: 2020-01-06 00:00:00+08:00 | D4: =LEFT(C4,4) -> 2020 | E4: =A4*B4 -> 1.7795049e+08
A5: 7.8918605 | B5: 14932593 | C5: 2020-01-07 00:00:00+08:00 | D5: =LEFT(C5,4) -> 2020 | E5: =A5*B5 -> 1.1784594e+08 | K5: Ср.Взвеш | L5: Прирост
A6: 8.0049477 | B6: 23531625 | C6: 2020-01-08 00:00:00+08:00 | D6: =LEFT(C6,4) -> 2020 | E6: =A6*B6 -> 1.8836943e+08
A7: 8.0453358 | B7: 17370472 | C7: 2020-01-09 00:00:00+08:00 | D7: =LEFT(C7,4) -> 2020 | E7: =A7*B7 -> 1.3975128e+08 | H7: 2020 | I7: =SUMIF(D:D,$H7,E:E) -> 5.0518192e+10 | J7: =SUMIF($D:$D,$H7,B:B) -> 8096596726 | K7: =I7/J7 -> 6.2394354
A8: 7.9968681 | B8: 24968948 | C8: 2020-01-10 00:00:00+08:00 | D8: =LEFT(C8,4) -> 2020 | E8: =A8*B8 -> 1.9967338e+08 | H8: 2021 | I8: =SUMIF(D:D,$H8,E:E) -> 6.182259e+10 | J8: =SUMIF($D:$D,$H8,B:B) -> 9631399971 | K8: =I8/J8 -> 6.4188581 | L8: =(K8-K7)*100/K7 -> 2.8756246
A9: 8.0534134 | B9: 24576715 | C9: 2020-01-13 00:00:00+08:00 | D9: =LEFT(C9,4) -> 2020 | E9: =A9*B9 -> 1.9792645e+08 | H9: 2022 | I9: =SUMIF(D:D,$H9,E:E) -> 3.0914e+10 | J9: =SUMIF($D:$D,$H9,B:B) -> 5239621311 | K9: =I9/J9 -> 5.9000447 | L9: =(K9-K8)*100/K8 -> -8.0826434
A10: 8.0453358 | B10: 26215160 | C10: 2020-01-14 00:00:00+08:00 | D10: =LEFT(C10,4) -> 2020 | E10: =A10*B10 -> 2.1090976e+08 | H10: 2023 | I10: =SUMIF(D:D,$H10,E:E) -> 1.5115907e+10 | J10: =SUMIF($D:$D,$H10,B:B) -> 3597783389 | K10: =I10/J10 -> 4.2014499 | L10: =(K10-K9)*100/K9 -> -28.789525
A11: 7.8837814 | B11: 25451066 | C11: 2020-01-15 00:00:00+08:00 | D11: =LEFT(C11,4) -> 2020 | E11: =A11*B11 -> 2.0065064e+08 | H11: 2024 | I11: =SUMIF(D:D,$H11,E:E) -> 2.0423991e+10 | J11: =SUMIF($D:$D,$H11,B:B) -> 6723509123 | K11: =I11/J11 -> 3.0376982 | L11: =(K11-K10)*100/K10 -> -27.698812
A12: 7.5849104 | B12: 48379052 | C12: 2020-01-16 00:00:00+08:00 | D12: =LEFT(C12,4) -> 2020 | E12: =A12*B12 -> 3.6695077e+08 | H12: 2025 | I12: =SUMIF(D:D,$H12,E:E) -> 2.2195333e+10 | J12: =SUMIF($D:$D,$H12,B:B) -> 6688228979 | K12: =I12/J12 -> 3.3185666 | L12: =(K12-K11)*100/K11 -> 9.2460947
A13: 7.5929866 | B13: 31934046 | C13: 2020-01-17 00:00:00+08:00 | D13: =LEFT(C13,4) -> 2020 | E13: =A13*B13 -> 2.4247478e+08
A14: 7.3345022 | B14: 38436797 | C14: 2020-01-20 00:00:00+08:00 | D14: =LEFT(C14,4) -> 2020 | E14: =A14*B14 -> 2.8191477e+08
A15: 6.9952416 | B15: 45352300 | C15: 2020-01-21 00:00:00+08:00 | D15: =LEFT(C15,4) -> 2020 | E15: =A15*B15 -> 3.172503e+08
A16: 7.1729498 | B16: 20966231 | C16: 2020-01-22 00:00:00+08:00 | D16: =LEFT(C16,4) -> 2020 | E16: =A16*B16 -> 1.5038972e+08
A17: 6.9629316 | B17: 15933661 | C17: 2020-01-23 00:00:00+08:00 | D17: =LEFT(C17,4) -> 2020 | E17: =A17*B17 -> 1.1094499e+08
A18: 7.0033183 | B18: 5822710 | C18: 2020-01-24 00:00:00+08:00 | D18: =LEFT(C18,4) -> 2020 | E18: =A18*B18 -> 40778292
A19: 6.7367573 | B19: 21202513 | C19: 2020-01-29 00:00:00+08:00 | D19: =LEFT(C19,4) -> 2020 | E19: =A19*B19 -> 1.4283618e+08
A20: 6.3974962 | B20: 38413862 | C20: 2020-01-30 00:00:00+08:00 | D20: =LEFT(C20,4) -> 2020 | E20: =A20*B20 -> 2.4575254e+08
A21: 6.3651848 | B21: 31738441 | C21: 2020-01-31 00:00:00+08:00 | D21: =LEFT(C21,4) -> 2020 | E21: =A21*B21 -> 2.0202104e+08
A22: 6.4378839 | B22: 47833214 | C22: 2020-02-03 00:00:00+08:00 | D22: =LEFT(C22,4) -> 2020 | E22: =A22*B22 -> 3.0794468e+08
A23: 6.5671263 | B23: 52086628 | C23: 2020-02-04 00:00:00+08:00 | D23: =LEFT(C23,4) -> 2020 | E23: =A23*B23 -> 3.4205946e+08
A24: 6.8094554 | B24: 38248856 | C24: 2020-02-05 00:00:00+08:00 | D24: =LEFT(C24,4) -> 2020 | E24: =A24*B24 -> 2.6045388e+08
... A1477: 4.0999999 | B1477: 0 | C1477: 2025-12-31 00:00:00+08:00 | D1477: =LEFT(C1477,4) -> 2025 | E1477: =A1477*B1477 -> 0

Sheet Mercedes-Benz
A1: Close | B1: Volume | C1: date | D1: Year | E1: Close * Volume
A2: 28.898634 | B2: 2973654 | C2: 2020-01-02 00:00:00+01:00 | D2: =LEFT(C2,4) -> 2020 | E2: =A2*B2 -> 85934538
A3: 28.375309 | B3: 4014262 | C3: 2020-01-03 00:00:00+01:00 | D3: =LEFT(C3,4) -> 2020 | E3: =A3*B3 -> 1.1390592e+08
A4: 28.222067 | B4: 3441396 | C4: 2020-01-06 00:00:00+01:00 | D4: =LEFT(C4,4) -> 2020 | E4: =A4*B4 -> 97123308
A5: 28.44759 | B5: 2816618 | C5: 2020-01-07 00:00:00+01:00 | D5: =LEFT(C5,4) -> 2020 | E5: =A5*B5 -> 80125994 | K5: Ср.Взвеш | L5: Прирост
A6: 28.606613 | B6: 2659070 | C6: 2020-01-08 00:00:00+01:00 | D6: =LEFT(C6,4) -> 2020 | E6: =A6*B6 -> 76066987
A7: 28.728046 | B7: 3098476 | C7: 2020-01-09 00:00:00+01:00 | D7: =LEFT(C7,4) -> 2020 | E7: =A7*B7 -> 89013162 | H7: 2020 | I7: =SUMIF(D:D,$H7,E:E) -> 3.6530363e+10 | J7: =SUMIF($D:$D,$H7,B:B) -> 1624738460 | K7: =I7/J7 -> 22.483842
A8: 28.583485 | B8: 3130777 | C8: 2020-01-10 00:00:00+01:00 | D8: =LEFT(C8,4) -> 2020 | E8: =A8*B8 -> 89488516 | H8: 2021 | I8: =SUMIF(D:D,$H8,E:E) -> 4.12596e+10 | J8: =SUMIF($D:$D,$H8,B:B) -> 919917116 | K8: =I8/J8 -> 44.851432 | L8: =(K8-K7)*100/K7 -> 99.482953
A9: 28.274111 | B9: 3089806 | C9: 2020-01-13 00:00:00+01:00 | D9: =LEFT(C9,4) -> 2020 | E9: =A9*B9 -> 87361517 | H9: 2022 | I9: =SUMIF(D:D,$H9,E:E) -> 3.6934551e+10 | J9: =SUMIF($D:$D,$H9,B:B) -> 774808094 | K9: =I9/J9 -> 47.669289 | L9: =(K9-K8)*100/K8 -> 6.2826465
A10: 28.019676 | B10: 4170529 | C10: 2020-01-14 00:00:00+01:00 | D10: =LEFT(C10,4) -> 2020 | E10: =A10*B10 -> 1.1685687e+08 | H10: 2023 | I10: =SUMIF(D:D,$H10,E:E) -> 3.5820513e+10 | J10: =SUMIF($D:$D,$H10,B:B) -> 636842714 | K10: =I10/J10 -> 56.247033 | L10: =(K10-K9)*100/K9 -> 17.994277
A11: 27.317089 | B11: 5857810 | C11: 2020-01-15 00:00:00+01:00 | D11: =LEFT(C11,4) -> 2020 | E11: =A11*B11 -> 1.6001832e+08 | H11: 2024 | I11: =SUMIF(D:D,$H11,E:E) -> 4.0126019e+10 | J11: =SUMIF($D:$D,$H11,B:B) -> 709602468 | K11: =I11/J11 -> 56.547181 | L11: =(K11-K10)*100/K10 -> 0.53362378
A12: 27.10602 | B12: 4517609 | C12: 2020-01-16 00:00:00+01:00 | D12: =LEFT(C12,4) -> 2020 | E12: =A12*B12 -> 1.224544e+08 | H12: 2025 | I12: =SUMIF(D:D,$H12,E:E) -> 2.4620901e+10 | J12: =SUMIF($D:$D,$H12,B:B) -> 477705582 | K12: =I12/J12 -> 51.539905 | L12: =(K12-K11)*100/K11 -> -8.8550396
A13: 26.999044 | B13: 4582967 | C13: 2020-01-17 00:00:00+01:00 | D13: =LEFT(C13,4) -> 2020 | E13: =A13*B13 -> 1.2373573e+08
A14: 26.92676 | B14: 2802010 | C14: 2020-01-20 00:00:00+01:00 | D14: =LEFT(C14,4) -> 2020 | E14: =A14*B14 -> 75449050
A15: 26.831347 | B15: 3320743 | C15: 2020-01-21 00:00:00+01:00 | D15: =LEFT(C15,4) -> 2020 | E15: =A15*B15 -> 89100006
A16: 26.261763 | B16: 8999759 | C16: 2020-01-22 00:00:00+01:00 | D16: =LEFT(C16,4) -> 2020 | E16: =A16*B16 -> 2.3634953e+08
A17: 25.692173 | B17: 5682839 | C17: 2020-01-23 00:00:00+01:00 | D17: =LEFT(C17,4) -> 2020 | E17: =A17*B17 -> 1.4600448e+08
A18: 25.408823 | B18: 5996104 | C18: 2020-01-24 00:00:00+01:00 | D18: =LEFT(C18,4) -> 2020 | E18: =A18*B18 -> 1.5235395e+08
A19: 24.619499 | B19: 6571183 | C19: 2020-01-27 00:00:00+01:00 | D19: =LEFT(C19,4) -> 2020 | E19: =A19*B19 -> 1.6177923e+08
A20: 25.030064 | B20: 6708750 | C20: 2020-01-28 00:00:00+01:00 | D20: =LEFT(C20,4) -> 2020 | E20: =A20*B20 -> 1.6792044e+08
A21: 25.105238 | B21: 3965600 | C21: 2020-01-29 00:00:00+01:00 | D21: =LEFT(C21,4) -> 2020 | E21: =A21*B21 -> 99557332
A22: 24.743824 | B22: 3977028 | C22: 2020-01-30 00:00:00+01:00 | D22: =LEFT(C22,4) -> 2020 | E22: =A22*B22 -> 98406881
A23: 24.174236 | B23: 6017511 | C23: 2020-01-31 00:00:00+01:00 | D23: =LEFT(C23,4) -> 2020 | E23: =A23*B23 -> 1.4546873e+08
A24: 24.067257 | B24: 4874196 | C24: 2020-02-03 00:00:00+01:00 | D24: =LEFT(C24,4) -> 2020 | E24: =A24*B24 -> 1.1730853e+08
... A1477: 52.290001 | B1477: 1425624 | C1477: 2025-10-14 00:00:00+02:00 | D1477: =LEFT(C1477,4) -> 2025 | E1477: =A1477*B1477 -> 74545880
A1478: 52.360001 | B1478: 1607016 | C1478: 2025-10-15 00:00:00+02:00
A1479: 52.73 | B1479: 1652645 | C1479: 2025-10-16 00:00:00+02:00
A1480: 53.369999 | B1480: 2238171 | C1480: 2025-10-17 00:00:00+02:00
A1481: 53.830002 | B1481: 1778475 | C1481: 2025-10-20 00:00:00+02:00
A1482: 54.169998 | B1482: 1457931 | C1482: 2025-10-21 00:00:00+02:00
A1483: 52.959999 | B1483: 2535227 | C1483: 2025-10-22 00:00:00+02:00
A1484: 53.200001 | B1484: 1484645 | C1484: 2025-10-23 00:00:00+02:00
A1485: 53.75 | B1485: 1270305 | C1485: 2025-10-24 00:00:00+02:00
A1486: 53.990002 | B1486: 1423938 | C1486: 2025-10-27 00:00:00+01:00
A1487: 54.650002 | B1487: 2531811 | C1487: 2025-10-28 00:00:00+01:00
A1488: 57.040001 | B1488: 6427763 | C1488: 2025-10-29 00:00:00+01:00
A1489: 56.43 | B1489: 2579469 | C1489: 2025-10-30 00:00:00+01:00
... A1529: 60.07 | B1529: 1017759 | C1529: 2025-12-30 00:00:00+01:00

Sheet LiAuto
A1: Close | B1: Volume | C1: date | D1: Year | E1: Close * Volume
A2: 117 | B2: 5750078 | C2: 2021-08-12 00:00:00+08:00 | D2: =LEFT(C2,4) -> 2021 | E2: =A2*B2 -> 672759126
A3: 114.6 | B3: 2584404 | C3: 2021-08-13 00:00:00+08:00 | D3: =LEFT(C3,4) -> 2021 | E3: =A3*B3 -> 2.9617269e+08
A4: 106.4 | B4: 4011220 | C4: 2021-08-16 00:00:00+08:00 | D4: =LEFT(C4,4) -> 2021 | E4: =A4*B4 -> 4.2679381e+08
A5: 106.3 | B5: 753900 | C5: 2021-08-17 00:00:00+08:00 | D5: =LEFT(C5,4) -> 2021 | E5: =A5*B5 -> 80139572 | K5: Ср.Взвеш | L5: Прирост
A6: 111.4 | B6: 1364600 | C6: 2021-08-18 00:00:00+08:00 | D6: =LEFT(C6,4) -> 2021 | E6: =A6*B6 -> 1.5201644e+08
A7: 108.9 | B7: 423400 | C7: 2021-08-19 00:00:00+08:00 | D7: =LEFT(C7,4) -> 2021 | E7: =A7*B7 -> 46108261 | H7: 2020 | I7: =SUMIF(D:D,$H7,E:E) -> 0 | J7: =SUMIF($D:$D,$H7,B:B) -> 0 | K7: =I7/J7 -> #DIV/0!
A8: 104.6 | B8: 792950 | C8: 2021-08-20 00:00:00+08:00 | D8: =LEFT(C8,4) -> 2021 | E8: =A8*B8 -> 82942569 | H8: 2021 | I8: =SUMIF(D:D,$H8,E:E) -> 9.8566622e+09 | J8: =SUMIF($D:$D,$H8,B:B) -> 82522185 | K8: =I8/J8 -> 119.44257 | L8: =(K8-K7)*100/K7 -> #DIV/0!
A9: 111.3 | B9: 769900 | C9: 2021-08-23 00:00:00+08:00 | D9: =LEFT(C9,4) -> 2021 | E9: =A9*B9 -> 85689872 | H9: 2022 | I9: =SUMIF(D:D,$H9,E:E) -> 1.5857221e+11 | J9: =SUMIF($D:$D,$H9,B:B) -> 1610153024 | K9: =I9/J9 -> 98.482697 | L9: =(K9-K8)*100/K8 -> -17.54808
A10: 115.2 | B10: 814100 | C10: 2021-08-24 00:00:00+08:00 | D10: =LEFT(C10,4) -> 2021 | E10: =A10*B10 -> 93784318 | H10: 2023 | I10: =SUMIF(D:D,$H10,E:E) -> 2.247317e+11 | J10: =SUMIF($D:$D,$H10,B:B) -> 1819764493 | K10: =I10/J10 -> 123.49494 | L10: =(K10-K9)*100/K9 -> 25.3976
A11: 117.8 | B11: 997600 | C11: 2021-08-25 00:00:00+08:00 | D11: =LEFT(C11,4) -> 2021 | E11: =A11*B11 -> 1.1751728e+08 | H11: 2024 | I11: =SUMIF(D:D,$H11,E:E) -> 2.9232107e+11 | J11: =SUMIF($D:$D,$H11,B:B) -> 2896529929 | K11: =I11/J11 -> 100.92113 | L11: =(K11-K10)*100/K10 -> -18.279138
A12: 116 | B12: 368500 | C12: 2021-08-26 00:00:00+08:00 | D12: =LEFT(C12,4) -> 2021 | E12: =A12*B12 -> 42746000 | H12: 2025 | I12: =SUMIF(D:D,$H12,E:E) -> 4.0726307e+11 | J12: =SUMIF($D:$D,$H12,B:B) -> 4139603761 | K12: =I12/J12 -> 98.382138 | L12: =(K12-K11)*100/K11 -> -2.5158166
A13: 116.7 | B13: 307900 | C13: 2021-08-27 00:00:00+08:00 | D13: =LEFT(C13,4) -> 2021 | E13: =A13*B13 -> 35931929
A14: 115.2 | B14: 272550 | C14: 2021-08-30 00:00:00+08:00 | D14: =LEFT(C14,4) -> 2021 | E14: =A14*B14 -> 31397759
A15: 114.6 | B15: 535300 | C15: 2021-08-31 00:00:00+08:00 | D15: =LEFT(C15,4) -> 2021 | E15: =A15*B15 -> 61345379
A16: 119 | B16: 907850 | C16: 2021-09-01 00:00:00+08:00 | D16: =LEFT(C16,4) -> 2021 | E16: =A16*B16 -> 108034150
A17: 118.8 | B17: 701190 | C17: 2021-09-02 00:00:00+08:00 | D17: =LEFT(C17,4) -> 2021 | E17: =A17*B17 -> 83301374
A18: 118.5 | B18: 1950600 | C18: 2021-09-03 00:00:00+08:00 | D18: =LEFT(C18,4) -> 2021 | E18: =A18*B18 -> 231146100
A19: 118.3 | B19: 153200 | C19: 2021-09-06 00:00:00+08:00 | D19: =LEFT(C19,4) -> 2021 | E19: =A19*B19 -> 18123560
A20: 121 | B20: 797100 | C20: 2021-09-07 00:00:00+08:00 | D20: =LEFT(C20,4) -> 2021 | E20: =A20*B20 -> 96449100
A21: 121.2 | B21: 452845 | C21: 2021-09-08 00:00:00+08:00 | D21: =LEFT(C21,4) -> 2021 | E21: =A21*B21 -> 54884813
A22: 115.9 | B22: 362910 | C22: 2021-09-09 00:00:00+08:00 | D22: =LEFT(C22,4) -> 2021 | E22: =A22*B22 -> 42061270
A23: 118.9 | B23: 594655 | C23: 2021-09-10 00:00:00+08:00 | D23: =LEFT(C23,4) -> 2021 | E23: =A23*B23 -> 70704480
A24: 117.2 | B24: 483800 | C24: 2021-09-13 00:00:00+08:00 | D24: =LEFT(C24,4) -> 2021 | E24: =A24*B24 -> 56701359
... A1079: 64.650002 | B1079: 0 | C1079: 2025-12-31 00:00:00+08:00 | D1079: =LEFT(C1079,4) -> 2025 | E1079: =A1079*B1079 -> 0
D1080: =LEFT(C1080,4) | E1080: =A1080*B1080 -> 0
D1081: =LEFT(C1081,4) | E1081: =A1081*B1081 -> 0
D1082: =LEFT(C1082,4) | E1082: =A1082*B1082 -> 0
D1083: =LEFT(C1083,4) | E1083: =A1083*B1083 -> 0
D1084: =LEFT(C1084,4) | E1084: =A1084*B1084 -> 0
D1085: =LEFT(C1085,4) | E1085: =A1085*B1085 -> 0
D1086: =LEFT(C1086,4) | E1086: =A1086*B1086 -> 0
D1087: =LEFT(C1087,4) | E1087: =A1087*B1087 -> 0
D1088: =LEFT(C1088,4) | E1088: =A1088*B1088 -> 0
D1089: =LEFT(C1089,4) | E1089: =A1089*B1089 -> 0
D1090: =LEFT(C1090,4) | E1090: =A1090*B1090 -> 0
D1091: =LEFT(C1091,4) | E1091: =A1091*B1091 -> 0
... D1477: =LEFT(C1477,4) | E1477: =A1477*B1477 -> 0

Sheet Geely
A1: Close | B1: Volume | C1: date | D1: Year | E1: Close * Volume
A2: 13.987068 | B2: 43850599 | C2: 2020-01-02 00:00:00+08:00 | D2: =LEFT(C2,4) -> 2020 | E2: =A2*B2 -> 6.1334132e+08
A3: 14.130525 | B3: 85452600 | C3: 2020-01-03 00:00:00+08:00 | D3: =LEFT(C3,4) -> 2020 | E3: =A3*B3 -> 1.2074901e+09
A4: 13.843609 | B4: 37967642 | C4: 2020-01-06 00:00:00+08:00 | D4: =LEFT(C4,4) -> 2020 | E4: =A4*B4 -> 5.2560919e+08
A5: 14.058795 | B5: 54555489 | C5: 2020-01-07 00:00:00+08:00 | D5: =LEFT(C5,4) -> 2020 | E5: =A5*B5 -> 7.6698443e+08 | K5: Ср.Взвеш | L5: Прирост
A6: 13.93327 | B6: 29886407 | C6: 2020-01-08 00:00:00+08:00 | D6: =LEFT(C6,4) -> 2020 | E6: =A6*B6 -> 4.1641539e+08
A7: 14.417439 | B7: 44723813 | C7: 2020-01-09 00:00:00+08:00 | D7: =LEFT(C7,4) -> 2020 | E7: =A7*B7 -> 6.4480282e+08 | H7: 2020 | I7: =SUMIF(D:D,$H7,E:E) -> 2.7391427e+11 | J7: =SUMIF($D:$D,$H7,B:B) -> 18699976446 | K7: =I7/J7 -> 14.64784
A8: 14.34571 | B8: 35089769 | C8: 2020-01-10 00:00:00+08:00 | D8: =LEFT(C8,4) -> 2020 | E8: =A8*B8 -> 5.0338764e+08 | H8: 2021 | I8: =SUMIF(D:D,$H8,E:E) -> 4.2913203e+11 | J8: =SUMIF($D:$D,$H8,B:B) -> 18490206965 | K8: =I8/J8 -> 23.208611 | L8: =(K8-K7)*100/K7 -> 58.443913
A9: 14.650556 | B9: 34464906 | C9: 2020-01-13 00:00:00+08:00 | D9: =LEFT(C9,4) -> 2020 | E9: =A9*B9 -> 5.0493002e+08 | H9: 2022 | I9: =SUMIF(D:D,$H9,E:E) -> 2.1411273e+11 | J9: =SUMIF($D:$D,$H9,B:B) -> 16682567349 | K9: =I9/J9 -> 12.834519 | L9: =(K9-K8)*100/K8 -> -44.699323
